Workbook

Sheet اجمالى 9
B1: العدد | C1: اجمالى | D1: الجمالى مدفوع | E1: مديونيات | G1: اجمالى عدد الاشتراكات | H1: اجمالى اشتراكات | I1: اجمالى مدفوع | J1: اجمالى مديونيات | K1: اجمالى مصاريف | L1: اجمالى | M1: الشهر
A2: شهر رجال | B2: =COUNTIFS(#REF!,"شهر",#REF!,"رجال") -> #REF! | C2: =SUMIFS(#REF!,#REF!, "شهر",#REF!, "رجال") -> #REF! | D2: =SUMIFS(#REF!,#REF!, "شهر",#REF!, "رجال") -> #REF! | E2: =C2-D2 -> #REF! | G2: =SUM(B2:B27) -> #REF! | H2: =SUM(C2:C28) -> #REF! | I2: =SUM(D2:D28) -> #REF! | J2: =SUM(E2:E28) -> #REF! | K2: =SUM('مصاريف 9'!B:B) -> #REF! | L2: =I2-K2 -> #REF! | M2: 9
A3: شهر سيدات | B3: =COUNTIFS(#REF!,"شهر",#REF!,"سيدات") -> #REF! | C3: =SUMIFS(#REF!,#REF!, "شهر",#REF!, "سيدات") -> #REF! | D3: =SUMIFS(#REF!,#REF!, "شهر",#REF!, "سيدات") -> #REF! | E3: =C3-D3 -> #REF!
A4: شهرين رجال | B4: =COUNTIFS(#REF!,"شهرين",#REF!,"رجال") -> #REF! | C4: =SUMIFS(#REF!,#REF!, "شهرين",#REF!, "رجال") -> #REF! | D4: =SUMIFS(#REF!,#REF!, "شهرين",#REF!, "رجال") -> #REF! | E4: =C4-D4 -> #REF! | G4: اجمالى عدد الاشتراكات | H4: اجمالى اشتراكات | I4: اجمالى مدفوع | J4: اجمالى مديونيات | K4: اجمالى مصاريف | L4: اجمالى | M4: الشهر
A5: شهرين سيدات | B5: =COUNTIFS(#REF!,"شهرين",#REF!,"سيدات") -> #REF! | C5: =SUMIFS(#REF!,#REF!, "شهرين",#REF!, "سيدات") -> #REF! | D5: =SUMIFS(#REF!,#REF!, "شهرين",#REF!, "سيدات") -> #REF! | E5: =C5-D5 -> #REF! | G5: 119 | H5: 154480 | I5: 132730 | J5: 21750 | K5: 84695 | L5: 48035 | M5: 9
A6: 3 شهور رجال | B6: =COUNTIFS(#REF!,"3 شهور",#REF!,"رجال") -> #REF! | C6: =SUMIFS(#REF!,#REF!, "3 شهور",#REF!, "رجال") -> #REF! | D6: =SUMIFS(#REF!,#REF!, "3 شهور",#REF!, "رجال") -> #REF! | E6: =C6-D6 -> #REF!
A7: 3 شهور سيدات | B7: =COUNTIFS(#REF!,"3 شهور",#REF!,"سيدات") -> #REF! | C7: =SUMIFS(#REF!,#REF!, "3 شهور",#REF!, "سيدات") -> #REF! | D7: =SUMIFS(#REF!,#REF!, "3 شهور",#REF!, "سيدات") -> #REF! | E7: =C7-D7 -> #REF!
A8: 6 شهور رجال | B8: =COUNTIFS(#REF!,"6 شهور",#REF!,"رجال") -> #REF! | C8: =SUMIFS(#REF!,#REF!, "6 شهور",#REF!, "رجال") -> #REF! | D8: =SUMIFS(#REF!,#REF!, "6 شهور",#REF!, "رجال") -> #REF! | E8: =C8-D8 -> #REF!
A9: 6 شهور سيدات | B9: =COUNTIFS(#REF!,"6 شهور",#REF!,"سيدات") -> #REF! | C9: =SUMIFS(#REF!,#REF!, "6 شهور",#REF!, "سيدات") -> #REF! | D9: =SUMIFS(#REF!,#REF!, "6 شهور",#REF!, "سيدات") -> #REF! | E9: =C9-D9 -> #REF!
A10: سنة رجال | B10: =COUNTIFS(#REF!,"سنة",#REF!,"رجال") -> #REF! | C10: =SUMIFS(#REF!,#REF!, "سنة",#REF!, "رجال") -> #REF! | D10: =SUMIFS(#REF!,#REF!, "سنة",#REF!, "رجال") -> #REF! | E10: =C10-D10 -> #REF!
A11: سنة سيدات | B11: =COUNTIFS(#REF!,"سنة",#REF!,"سيدات") -> #REF! | C11: =SUMIFS(#REF!,#REF!, "سنة",#REF!, "سيدات") -> #REF! | D11: =SUMIFS(#REF!,#REF!, "سنة",#REF!, "سيدات") -> #REF! | E11: =C11-D11 -> #REF!
A12: برايفت 6 حصص رجال | B12: =COUNTIFS(#REF!,"برايفت 6 حصص",#REF!,"رجال") -> #REF! | C12: =SUMIFS(#REF!,#REF!, "برايفت 6 حصص",#REF!, "رجال") -> #REF! | D12: =SUMIFS(#REF!,#REF!, "برايفت 6 حصص",#REF!, "رجال") -> #REF! | E12: =C12-D12 -> #REF!
A13: برايفت 6 حصص سيدات | B13: =COUNTIFS(#REF!,"برايفت 6 حصص",#REF!,"سيدات") -> #REF! | C13: =SUMIFS(#REF!,#REF!, "برايفت 6 حصص",#REF!, "سيدات") -> #REF! | D13: =SUMIFS(#REF!,#REF!, "برايفت 6 حصص",#REF!, "سيدات") -> #REF! | E13: =C13-D13 -> #REF!
A14: برايفت 10 حصص رجال | B14: =COUNTIFS(#REF!,"برايفت 10 حصص",#REF!,"رجال") -> #REF! | C14: =SUMIFS(#REF!,#REF!, "برايفت 10 حصص",#REF!, "رجال") -> #REF! | D14: =SUMIFS(#REF!,#REF!, "برايفت 10 حصص",#REF!, "رجال") -> #REF! | E14: =C14-D14 -> #REF!
A15: برايفت 10 حصص سيدات | B15: =COUNTIFS(#REF!,"برايفت 10 حصص",#REF!,"سيدات") -> #REF! | C15: =SUMIFS(#REF!,#REF!, "برايفت 10 حصص",#REF!, "سيدات") -> #REF! | D15: =SUMIFS(#REF!,#REF!, "برايفت 10 حصص",#REF!, "سيدات") -> #REF! | E15: =C15-D15 -> #REF!
A16: برايفت 15 حصة رجال | B16: =COUNTIFS(#REF!,"برايفت 15 حصص",#REF!,"رجال") -> #REF! | C16: =SUMIFS(#REF!,#REF!, "برايفت 15 حصص",#REF!, "رجال") -> #REF! | D16: =SUMIFS(#REF!,#REF!, "برايفت 15 حصص",#REF!, "رجال") -> #REF! | E16: =C16-D16 -> #REF!
A17: برايفت 15 حصة سيدات | B17: =COUNTIFS(#REF!,"برايفت 15 حصص",#REF!,"سيدات") -> #REF! | C17: =SUMIFS(#REF!,#REF!, "برايفت 15 حصص",#REF!, "سيدات") -> #REF! | D17: =SUMIFS(#REF!,#REF!, "برايفت 15 حصص",#REF!, "سيدات") -> #REF! | E17: =C17-D17 -> #REF!
A18: برايفت 20 حصة رجال | B18: =COUNTIFS(#REF!,"برايفت 20 حصص",#REF!,"رجال") -> #REF! | C18: =SUMIFS(#REF!,#REF!, "برايفت 20 حصص",#REF!, "رجال") -> #REF! | D18: =SUMIFS(#REF!,#REF!, "برايفت 20 حصص",#REF!, "رجال") -> #REF! | E18: =C18-D18 -> #REF!
A19: برايفت 20 حصة سيدات | B19: =COUNTIFS(#REF!,"برايفت 20 حصص",#REF!,"سيدات") -> #REF! | C19: =SUMIFS(#REF!,#REF!, "برايفت 20 حصص",#REF!, "سيدات") -> #REF! | D19: =SUMIFS(#REF!,#REF!, "برايفت 20 حصص",#REF!, "سيدات") -> #REF! | E19: =C19-D19 -> #REF!
A20: حصة برايفت رجال | B20: =COUNTIFS(#REF!,"حصة برايفت",#REF!,"رجال") -> #REF! | C20: =SUMIFS(#REF!,#REF!, "حصة برايفت",#REF!, "رجال") -> #REF! | D20: =SUMIFS(#REF!,#REF!, "حصة برايفت",#REF!, "رجال") -> #REF! | E20: =C20-D20 -> #REF!
A21: حصة برايفت سيدات | B21: =COUNTIFS(#REF!,"حصة برايفت",#REF!,"سيدات") -> #REF! | C21: =SUMIFS(#REF!,#REF!, "حصة برايفت",#REF!, "سيدات") -> #REF! | D21: =SUMIFS(#REF!,#REF!, "حصة برايفت",#REF!, "سيدات") -> #REF! | E21: =C21-D21 -> #REF!
A22: جدول تدريب رجال | B22: =COUNTIFS(#REF!,"جدول تدريب",#REF!,"رجال") -> #REF! | C22: =SUMIFS(#REF!,#REF!, "جدول تدريب",#REF!, "رجال") -> #REF! | D22: =SUMIFS(#REF!,#REF!, "جدول تدريب",#REF!, "رجال") -> #REF! | E22: =C22-D22 -> #REF!
A23: جدول تدريب سيدات | B23: =COUNTIFS(#REF!,"جدول تدريب",#REF!,"سيدات") -> #REF! | C23: =SUMIFS(#REF!,#REF!, "جدول تدريب",#REF!, "سيدات") -> #REF! | D23: =SUMIFS(#REF!,#REF!, "جدول تدريب",#REF!, "سيدات") -> #REF! | E23: =C23-D23 -> #REF!
A24: جدول تغذية رجال | B24: =COUNTIFS(#REF!,"جدول تغذية",#REF!,"رجال") -> #REF! | C24: =SUMIFS(#REF!,#REF!, "جدول تغذية",#REF!, "رجال") -> #REF! | D24: =SUMIFS(#REF!,#REF!, "جدول تغذية",#REF!, "رجال") -> #REF! | E24: =C24-D24 -> #REF!
A25: جدول تغذية سيدات | B25: =COUNTIFS(#REF!,"جدول تغذية",#REF!,"سيدات") -> #REF! | C25: =SUMIFS(#REF!,#REF!, "جدول تغذية",#REF!, "سيدات") -> #REF! | D25: =SUMIFS(#REF!,#REF!, "جدول تغذية",#REF!, "سيدات") -> #REF! | E25: =C25-D25 -> #REF!
A26: حصة يومي | B26: =COUNTIFS(#REF!,"حصة يومي") -> #REF! | C26: =SUMIFS(#REF!,#REF!, "حصة يومي") -> #REF! | D26: =SUMIFS(#REF!,#REF!, "حصة يومي") -> #REF! | E26: =C26-D26 -> #REF!
A27: غرامة | B27: =COUNTIFS(#REF!,"غرامة") -> #REF! | C27: =SUMIFS(#REF!,#REF!, "غرامة") -> #REF! | D27: =SUMIFS(#REF!,#REF!, "غرامة") -> #REF! | E27: =C27-D27 -> #REF!

Sheet مصاريف 9
A1: البند | B1: المبلغ | C1: التاريخ | F1: اجمالى
A2: مرتبات | B2: =SUM(' 9مرتبات'!B:B) -> #REF! | C2: 45930 | F2: =SUM(B:B) -> #REF!
A3: ايجار | B3: 10000 | C3: 45916
A4: أدوات كابل | B4: 7150 | C4: 45916
A5: نقل أدوات كابل | B5: 100 | C5: 45916
A6: سرنجة | B6: 15 | C6: 45916
A7: مادليات مفاتيح | B7: 100 | C7: 45916
A8: شيكولاتة | B8: 800 | C8: 45916
A9: أدوات نظافة | B9: 430 | C9: 45916
A10: نقل الثلاجة | B10: 200 | C10: 45916
A11: 4 زرعة رسيبشن | B11: 950 | C11: 45916
A12: مروحة سقف+مروحة استاند | B12: 1800 | C12: 45916
A13: 5 فوط | B13: 100 | C13: 45916
A14: موبيل | B14: 4800 | C14: 45916
... A29: شحن كهرباء | B29: 110 | C29: 45922
A30: مصروفات نقل أجهزة | B30: 1600 | C30: 45924 | D30: احمد مجدى
A31: شحن كهرباء | B31: 520 | C31: 45924 | D31: احمد مجدى
A32: تركيب أجهزة | B32: 1000 | C32: 45925
A33: مناديل5 باكتات | B33: 650 | C33: 45925
A34: ايجار شهر 9 | B34: 20000 | C34: 45930
A35: اشتراك النت | B35: 390 | C35: 45925
A36: شحن كهرباء | B36: 200 | C36: 45927
A37: شحن كهرباء | B37: 200 | C37: 45928
A38: نقل اوربتراك | B38: 500 | C38: 45930
A39: خراطة أجهزة | B39: 250 | C39: 45930
A40: شحن كهرباء | B40: 310 | C40: 45930

Sheet  9مرتبات
A1: كابتن ياسين | B1: 2500
A2: كابتن خالد | B2: 3000
A3: كابتن بسمة | B3: 3000
A4: وليد | B4: 2500
A5: مصطفى | B5: 5000
A6: محمد خالد | B6: 2000
A7: معتز | B7: 670
A8: برايفت كابتن خالد | B8: =SUMIF(#REF!, "كابتن خالد",#REF!)/2 -> #REF!
A9: برايفت كابتن ياسين | B9: =SUMIF(#REF!, "كابتن ياسين",#REF!)/2 -> #REF!
A10: برايفت كابتن بسمة | B10: =SUMIF(#REF!, "كابتن بسمة",#REF!)/2 -> #REF!

Sheet الاشتراكات
A1: الاسم | B1: التليفون | C1: الكود | D1: نوع الاشتراك | E1: سعر الاشتراك | F1: المبلغ المدفوع | G1: المبلغ المتبقى | H1: الدفع | I1: ملحوظات | J1: تاريخ التسجيل | K1: النوع | L1: Column2 | O1: 3 شهور | P1: كابتن بسمة | Q1: رجال | R1: كاش
A2: احمد وائل متولى | C2: 229 | D2: باقي الاشتراك | E2: 1500 | F2: 1500 | G2: =E2-F2 -> 0 | H2: كاش | J2: 01-02-2026 | K2: رجال | O2: باقي الاشتراك | P2: كابتن ياسين | Q2: سيدات | R2: انستاباى
A3: نزار عبدالمنعم | B3: 01015441888 | C3: 234 | D3: شهر | E3: 600 | F3: 600 | G3: =E3-F3 -> 0 | H3: كاش | J3: 01-02-2026 | K3: رجال | O3: برايفت 10 حصص | P3: كابتن خالد | R3: فودافون كاش
A4: سامى سمير | C4: 0001 | D4: حصة يومي | E4: 100 | F4: 100 | G4: =E4-F4 -> 0 | H4: كاش | J4: 02-02-2026 | K4: رجال | O4: برايفت 15 حصص | P4: كابتن اشرقت
A5: فاطمة على | B5: 01098167718 | C5: 349 | D5: 3 شهور | E5: 1600 | F5: 500 | G5: =E5-F5 -> 1100 | H5: فودافون كاش | J5: 03-02-2026 | K5: سيدات | O5: برايفت 20 حصص
A6: رباب محمد | B6: 01026514510 | C6: 350 | D6: 3 شهور | E6: 1600 | F6: 500 | G6: =E6-F6 -> 1100 | H6: كاش | J6: 03-02-2026 | K6: سيدات | O6: برايفت 30 حصص
A7: احمد نبيل | C7: 235 | D7: شهر | E7: 600 | F7: 600 | G7: =E7-F7 -> 0 | H7: كاش | J7: 04-02-2026 | K7: رجال | O7: برايفت 6 حصص
A8: عبدالرحمن مصطفى | C8: 225 | D8: شهر | E8: 500 | F8: 500 | G8: =E8-F8 -> 0 | H8: كاش | J8: 04-02-2026 | K8: رجال | O8: حصة يومي
A9: ياسين هشام | B9: 01149222822 | C9: 172 | D9: برايفت 10 حصص | E9: 1000 | F9: 1000 | G9: =E9-F9 -> 0 | H9: كاش | I9: كابتن خالد | J9: 05-02-2026 | K9: رجال | O9: سنة
A10: معز مجدى | B10: 01013900897 | C10: 161 | D10: شهر | E10: 600 | F10: 600 | G10: =E10-F10 -> 0 | H10: انستاباى | J10: 06-02-2026 | K10: رجال | O10: شهر
A11: معز مجدى | B11: 01013900897 | C11: 161 | D11: برايفت 10 حصص | E11: 1000 | F11: 1000 | G11: =E11-F11 -> 0 | H11: انستاباى | I11: كابتن خالد | J11: 06-02-2026 | K11: رجال | O11: 6 شهور
A12: مازن مجدى | B12: 01013900784 | C12: 149 | D12: شهر | E12: 600 | F12: 600 | G12: =E12-F12 -> 0 | H12: انستاباى | J12: 06-02-2026 | K12: رجال | O12: برايفت 8 حصص
A13: مازن مجدى | B13: 01013900784 | C13: 149 | D13: برايفت 10 حصص | E13: 1000 | F13: 1000 | G13: =E13-F13 -> 0 | H13: انستاباى | I13: كابتن خالد | J13: 06-02-2026 | K13: رجال
A14: مصطفى صبحى | B14: 01080792679 | C14: 216 | D14: باقي الاشتراك | E14: 200 | F14: 200 | G14: =E14-F14 -> 0 | H14: كاش | J14: 06-02-2026 | K14: رجال
A15: سمر عبدالناصر | C15: 348 | D15: باقي الاشتراك | E15: 300 | F15: 300 | G15: =E15-F15 -> 0 | H15: كاش | J15: 07-02-2026 | K15: سيدات
A16: عبدالرحمن اشرف | B16: 01151429714 | C16: 261 | D16: 6 شهور | E16: 2600 | F16: 2600 | G16: =E16-F16 -> 0 | H16: انستاباى | J16: 07-02-2026 | K16: رجال
A17: محمد عليوة | B17: 01008989751 | C17: 262 | D17: 3 شهور | E17: 1400 | F17: 1400 | G17: =E17-F17 -> 0 | H17: كاش | J17: 07-02-2026 | K17: رجال
A18: محمد جوهر | C18: 226 | D18: شهر | E18: 500 | F18: 500 | G18: =E18-F18 -> 0 | H18: كاش | J18: 08-02-2026 | K18: رجال
A19: رشا سبيل | C19: 309 | D19: برايفت 15 حصص | E19: 1200 | F19: 1200 | G19: =E19-F19 -> 0 | H19: كاش | I19: كابتن بسمة | J19: 08-02-2026 | K19: سيدات
A20: عبدالرحمن خميس | C20: 125 | D20: شهر | E20: 500 | F20: 500 | G20: =E20-F20 -> 0 | H20: كاش | J20: 09-02-2026 | K20: رجال
A21: محمد دسوقى | B21: 01001229934 | C21: 263 | D21: 6 شهور | E21: 2200 | F21: 2200 | G21: =E21-F21 -> 0 | H21: انستاباى | J21: 11-02-2026 | K21: رجال
A22: عبدالرحمن محمد | C22: 243 | D22: 3 شهور | E22: 1400 | F22: 1400 | G22: =E22-F22 -> 0 | H22: فودافون كاش | J22: 11-02-2026 | K22: رجال
A23: يوسف عربى | B23: 01010093238 | C23: 264 | D23: شهر | E23: 600 | F23: 600 | G23: =E23-F23 -> 0 | H23: كاش | J23: 11-02-2026 | K23: رجال
A24: محمود عغبدالمنعم | B24: 01155332484 | C24: 265 | D24: شهر | E24: 600 | F24: 600 | G24: =E24-F24 -> 0 | H24: كاش | J24: 11-02-2026 | K24: رجال
A25: اواب عبدالهادى | B25: 01001837825 | C25: 266 | D25: شهر | E25: 650 | F25: 650 | G25: =E25-F25 -> 0 | H25: كاش | J25: 11-02-2026 | K25: رجال
A26: إبراهيم عابدين | B26: 01055890794 | C26: 267 | D26: شهر | E26: 650 | F26: 650 | G26: =E26-F26 -> 0 | H26: كاش | J26: 11-02-2026 | K26: رجال
A27: بلال عمر | B27: 01022197026 | C27: 236 | D27: شهر | E27: 600 | F27: 600 | G27: =E27-F27 -> 0 | H27: كاش | J27: 11-02-2026 | K27: رجال
A28: عمرو محمد احمد | B28: 01097403113 | C28: 194 | D28: شهر | E28: 500 | F28: 500 | G28: =E28-F28 -> 0 | H28: كاش | J28: 18-02-2026 | K28: رجال
A29: محمود ابوالليل | B29: 01147909554 | C29: 268 | D29: شهر | E29: 500 | F29: 500 | G29: =E29-F29 -> 0 | H29: كاش | J29: 19-02-2026 | K29: رجال
A30: عمر غانم | B30: 01098376600 | C30: 269 | D30: شهر | E30: 500 | F30: 500 | G30: =E30-F30 -> 0 | H30: انستاباى | J30: 19-02-2026 | K30: رجال
A31: حسن حسام | B31: 01006637838 | C31: 270 | D31: شهر | E31: 500 | F31: 500 | G31: =E31-F31 -> 0 | H31: كاش | J31: 19-02-2026 | K31: رجال
A32: محمد مرزوق | B32: 0150549032 | C32: 271 | D32: شهر | E32: 500 | F32: 500 | G32: =E32-F32 -> 0 | H32: كاش | J32: 19-02-2026 | K32: رجال
A33: محمد المصطفى مبارك | B33: 249909128889 | C33: 272 | D33: شهر | E33: 500 | F33: 500 | G33: =E33-F33 -> 0 | H33: كاش | J33: 20-02-2026 | K33: رجال
A34: الغنوش مصطفى | B34: 249122010401 | C34: 273 | D34: شهر | E34: 500 | F34: 500 | G34: =E34-F34 -> 0 | H34: كاش | J34: 20-02-2026 | K34: رجال
A35: احمد عطية | C35: 173 | D35: باقي الاشتراك | E35: -1000 | F35: -1000 | G35: =E35-F35 -> 0 | H35: انستاباى | J35: 20-02-2026 | K35: رجال
A36: جنى احمد عطية | C36: 325 | D36: باقي الاشتراك | E36: 1500 | F36: 1500 | G36: =E36-F36 -> 0 | H36: انستاباى | J36: 20-02-2026 | K36: سيدات
A37: عبد الله احمد | C37: 174 | D37: باقي الاشتراك | E37: 1500 | F37: 1500 | G37: =E37-F37 -> 0 | H37: انستاباى | J37: 20-02-2026 | K37: رجال
A38: محمد المصطفى عثمان | C38: 274 | D38: شهر | E38: 500 | F38: 500 | G38: =E38-F38 -> 0 | H38: كاش | J38: 20-02-2026 | K38: رجال
A39: احمد ياسر | C39: 202 | D39: سنة | E39: 2800 | F39: 2800 | G39: =E39-F39 -> 0 | H39: كاش | J39: 21-02-2026 | K39: رجال
A40: الصادق هشام | C40: 230 | D40: شهر | E40: 500 | F40: 500 | G40: =E40-F40 -> 0 | H40: كاش | J40: 21-02-2026 | K40: رجال
...

Sheet اجمالى
B1: العدد | C1: اجمالى | D1: الجمالى مدفوع | E1: مديونيات | G1: اجمالى عدد الاشتراكات | H1: اجمالى اشتراكات | I1: اجمالى مدفوع | J1: اجمالى مديونيات | K1: اجمالى مصاريف | L1: اجمالى | M1: باقى لم يوزع | N1: الشهر
A2: شهر رجال | B2: =COUNTIFS(الاشتراكات!D:D,"شهر",الاشتراكات!K:K,"رجال") -> 32 | C2: =SUMIFS(الاشتراكات!E:E, الاشتراكات!D:D, "شهر", الاشتراكات!K:K, "رجال") -> 17000 | D2: =SUMIFS(الاشتراكات!F:F, الاشتراكات!D:D, "شهر", الاشتراكات!K:K, "رجال") -> 16800 | E2: =C2-D2 -> 200 | G2: 119 | H2: 154480 | I2: 132730 | J2: 21750 | K2: 84695 | L2: 48035 | M2: 0 | N2: 9
A3: شهر سيدات | B3: =COUNTIFS(الاشتراكات!D:D,"شهر",الاشتراكات!K:K,"سيدات") -> 3 | C3: =SUMIFS(الاشتراكات!E:E, الاشتراكات!D:D, "شهر", الاشتراكات!K:K, "سيدات") -> 1500 | D3: =SUMIFS(الاشتراكات!F:F, الاشتراكات!D:D, "شهر", الاشتراكات!K:K, "سيدات") -> 1500 | E3: =C3-D3 -> 0
A4: شهرين رجال | B4: =COUNTIFS(الاشتراكات!D:D,"شهرين",الاشتراكات!K:K,"رجال") -> 0 | C4: =SUMIFS(الاشتراكات!E:E, الاشتراكات!D:D, "شهرين", الاشتراكات!K:K, "رجال") -> 0 | D4: =SUMIFS(الاشتراكات!F:F, الاشتراكات!D:D, "شهرين", الاشتراكات!K:K, "رجال") -> 0 | E4: =C4-D4 -> 0 | G4: اجمالى عدد الاشتراكات | H4: اجمالى اشتراكات | I4: اجمالى مدفوع | J4: اجمالى مديونيات | K4: اجمالى مصاريف | L4: اجمالى | N4: الشهر
A5: شهرين سيدات | B5: =COUNTIFS(الاشتراكات!D:D,"شهرين",الاشتراكات!K:K,"سيدات") -> 0 | C5: =SUMIFS(الاشتراكات!E:E, الاشتراكات!D:D, "شهرين", الاشتراكات!K:K, "سيدات") -> 0 | D5: =SUMIFS(الاشتراكات!F:F, الاشتراكات!D:D, "شهرين", الاشتراكات!K:K, "سيدات") -> 0 | E5: =C5-D5 -> 0 | G5: 68 | H5: 87300 | I5: 68350 | J5: 18950 | K5: 50805 | L5: 17545 | M5: 0 | N5: 10
A6: 3 شهور رجال | B6: =COUNTIFS(الاشتراكات!D:D,"3 شهور",الاشتراكات!K:K,"رجال") -> 4 | C6: =SUMIFS(الاشتراكات!E:E, الاشتراكات!D:D, "3 شهور", الاشتراكات!K:K, "رجال") -> 5400 | D6: =SUMIFS(الاشتراكات!F:F, الاشتراكات!D:D, "3 شهور", الاشتراكات!K:K, "رجال") -> 5400 | E6: =C6-D6 -> 0
A7: 3 شهور سيدات | B7: =COUNTIFS(الاشتراكات!D:D,"3 شهور",الاشتراكات!K:K,"سيدات") -> 2 | C7: =SUMIFS(الاشتراكات!E:E, الاشتراكات!D:D, "3 شهور", الاشتراكات!K:K, "سيدات") -> 3200 | D7: =SUMIFS(الاشتراكات!F:F, الاشتراكات!D:D, "3 شهور", الاشتراكات!K:K, "سيدات") -> 1000 | E7: =C7-D7 -> 2200 | G7: اجمالى عدد الاشتراكات | H7: اجمالى اشتراكات | I7: اجمالى مدفوع | J7: اجمالى مديونيات | K7: اجمالى مصاريف | L7: اجمالى | N7: الشهر
A8: 6 شهور رجال | B8: =COUNTIFS(الاشتراكات!D:D,"6 شهور",الاشتراكات!K:K,"رجال") -> 2 | C8: =SUMIFS(الاشتراكات!E:E, الاشتراكات!D:D, "6 شهور", الاشتراكات!K:K, "رجال") -> 4800 | D8: =SUMIFS(الاشتراكات!F:F, الاشتراكات!D:D, "6 شهور", الاشتراكات!K:K, "رجال") -> 4800 | E8: =C8-D8 -> 0 | G8: 43 | H8: 53850 | I8: 45650 | J8: 8200 | K8: 42707 | L8: 2950 | M8: 2950 | N8: 11
A9: 6 شهور سيدات | B9: =COUNTIFS(الاشتراكات!D:D,"6 شهور",الاشتراكات!K:K,"سيدات") -> 0 | C9: =SUMIFS(الاشتراكات!E:E, الاشتراكات!D:D, "6 شهور", الاشتراكات!K:K, "سيدات") -> 0 | D9: =SUMIFS(الاشتراكات!F:F, الاشتراكات!D:D, "6 شهور", الاشتراكات!K:K, "سيدات") -> 0 | E9: =C9-D9 -> 0
A10: سنة رجال | B10: =COUNTIFS(الاشتراكات!D:D,"سنة",الاشتراكات!K:K,"رجال") -> 2 | C10: =SUMIFS(الاشتراكات!E:E, الاشتراكات!D:D, "سنة", الاشتراكات!K:K, "رجال") -> 5800 | D10: =SUMIFS(الاشتراكات!F:F, الاشتراكات!D:D, "سنة", الاشتراكات!K:K, "رجال") -> 5800 | E10: =C10-D10 -> 0
A11: سنة سيدات | B11: =COUNTIFS(الاشتراكات!D:D,"سنة",الاشتراكات!K:K,"سيدات") -> 0 | C11: =SUMIFS(الاشتراكات!E:E, الاشتراكات!D:D, "سنة", الاشتراكات!K:K, "سيدات") -> 0 | D11: =SUMIFS(الاشتراكات!F:F, الاشتراكات!D:D, "سنة", الاشتراكات!K:K, "سيدات") -> 0 | E11: =C11-D11 -> 0 | G11: اجمالى عدد الاشتراكات | H11: اجمالى اشتراكات | I11: اجمالى مدفوع | J11: اجمالى مديونيات | K11: اجمالى مصاريف | L11: اجمالى | N11: الشهر
A12: برايفت 6 حصص رجال | B12: =COUNTIFS(الاشتراكات!D:D,"برايفت 6 حصص",الاشتراكات!K:K,"رجال") -> 0 | C12: =SUMIFS(الاشتراكات!E:E, الاشتراكات!D:D, "برايفت 6 حصص", الاشتراكات!K:K, "رجال") -> 0 | D12: =SUMIFS(الاشتراكات!F:F, الاشتراكات!D:D, "برايفت 6 حصص", الاشتراكات!K:K, "رجال") -> 0 | E12: =C12-D12 -> 0 | G12: 69 | H12: 82200 | I12: 67300 | J12: 14900 | K12: 46925 | L12: 22000 | M12: 0 | N12: 12
A13: برايفت 6 حصص سيدات | B13: =COUNTIFS(الاشتراكات!D:D,"برايفت 6 حصص",الاشتراكات!K:K,"سيدات") -> 0 | C13: =SUMIFS(الاشتراكات!E:E, الاشتراكات!D:D, "برايفت 6 حصص", الاشتراكات!K:K, "سيدات") -> 0 | D13: =SUMIFS(الاشتراكات!F:F, الاشتراكات!D:D, "برايفت 6 حصص", الاشتراكات!K:K, "سيدات") -> 0 | E13: =C13-D13 -> 0
A14: برايفت 8 حصص رجال | B14: =COUNTIFS(الاشتراكات!D:D,"برايفت 8 حصص",الاشتراكات!K:K,"رجال") -> 0 | C14: =SUMIFS(الاشتراكات!E:E, الاشتراكات!D:D, "برايفت 8 حصص", الاشتراكات!K:K, "رجال") -> 0 | D14: =SUMIFS(الاشتراكات!F:F, الاشتراكات!D:D, "برايفت 8 حصص", الاشتراكات!K:K, "رجال") -> 0 | E14: =C14-D14 -> 0 | G14: اجمالى عدد الاشتراكات | H14: اجمالى اشتراكات | I14: اجمالى مدفوع | J14: اجمالى مديونيات | K14: اجمالى مصاريف | L14: اجمالى | N14: الشهر
A15: برايفت 8 حصص سيدات | B15: =COUNTIFS(الاشتراكات!D:D,"برايفت 8 حصص",الاشتراكات!K:K,"سيدات") -> 2 | C15: =SUMIFS(الاشتراكات!E:E, الاشتراكات!D:D, "برايفت 8 حصص", الاشتراكات!K:K, "سيدات") -> 2000 | D15: =SUMIFS(الاشتراكات!F:F, الاشتراكات!D:D, "برايفت 8 حصص", الاشتراكات!K:K, "سيدات") -> 2000 | E15: =C15-D15 -> 0 | G15: 73 | H15: 69850 | I15: 56100 | J15: 13750 | K15: 41615 | L15: 14335 | M15: 0 | N15: 1
A16: برايفت 10 حصص رجال | B16: =COUNTIFS(الاشتراكات!D:D,"برايفت 10 حصص",الاشتراكات!K:K,"رجال") -> 3 | C16: =SUMIFS(الاشتراكات!E:E, الاشتراكات!D:D, "برايفت 10 حصص", الاشتراكات!K:K, "رجال") -> 3000 | D16: =SUMIFS(الاشتراكات!F:F, الاشتراكات!D:D, "برايفت 10 حصص", الاشتراكات!K:K, "رجال") -> 3000 | E16: =C16-D16 -> 0
A17: برايفت 10 حصص سيدات | B17: =COUNTIFS(الاشتراكات!D:D,"برايفت 10 حصص",الاشتراكات!K:K,"سيدات") -> 0 | C17: =SUMIFS(الاشتراكات!E:E, الاشتراكات!D:D, "برايفت 10 حصص", الاشتراكات!K:K, "سيدات") -> 0 | D17: =SUMIFS(الاشتراكات!F:F, الاشتراكات!D:D, "برايفت 10 حصص", الاشتراكات!K:K, "سيدات") -> 0 | E17: =C17-D17 -> 0
A18: برايفت 15 حصة رجال | B18: =COUNTIFS(الاشتراكات!D:D,"برايفت 15 حصص",الاشتراكات!K:K,"رجال") -> 0 | C18: =SUMIFS(الاشتراكات!E:E, الاشتراكات!D:D, "برايفت 15 حصص", الاشتراكات!K:K, "رجال") -> 0 | D18: =SUMIFS(الاشتراكات!F:F, الاشتراكات!D:D, "برايفت 15 حصص", الاشتراكات!K:K, "رجال") -> 0 | E18: =C18-D18 -> 0 | G18: اجمالى عدد الاشتراكات | H18: اجمالى اشتراكات | I18: اجمالى مدفوع | J18: اجمالى مديونيات | K18: اجمالى مصاريف | L18: اجمالى | N18: الشهر
A19: برايفت 15 حصة سيدات | B19: =COUNTIFS(الاشتراكات!D:D,"برايفت 15 حصص",الاشتراكات!K:K,"سيدات") -> 1 | C19: =SUMIFS(الاشتراكات!E:E, الاشتراكات!D:D, "برايفت 15 حصص", الاشتراكات!K:K, "سيدات") -> 1200 | D19: =SUMIFS(الاشتراكات!F:F, الاشتراكات!D:D, "برايفت 15 حصص", الاشتراكات!K:K, "سيدات") -> 1200 | E19: =C19-D19 -> 0 | G19: =SUM(B2:B33) -> 61 | H19: =SUM(C2:C33) -> 48300 | I19: =SUM(D2:D33) -> 45900 | J19: =SUM(E2:E33) -> 2400 | K19: =SUM(مصاريف!B:B) -> 40540 | L19: =I19-K19 -> 5360 | N19: 2
A20: برايفت 20 حصة رجال | B20: =COUNTIFS(الاشتراكات!D:D,"برايفت 20 حصص",الاشتراكات!K:K,"رجال") -> 0 | C20: =SUMIFS(الاشتراكات!E:E, الاشتراكات!D:D, "برايفت 20 حصص", الاشتراكات!K:K, "رجال") -> 0 | D20: =SUMIFS(الاشتراكات!F:F, الاشتراكات!D:D, "برايفت 20 حصص", الاشتراكات!K:K, "رجال") -> 0 | E20: =C20-D20 -> 0
A21: برايفت 20 حصة سيدات | B21: =COUNTIFS(الاشتراكات!D:D,"برايفت 20 حصص",الاشتراكات!K:K,"سيدات") -> 0 | C21: =SUMIFS(الاشتراكات!E:E, الاشتراكات!D:D, "برايفت 20 حصص", الاشتراكات!K:K, "سيدات") -> 0 | D21: =SUMIFS(الاشتراكات!F:F, الاشتراكات!D:D, "برايفت 20 حصص", الاشتراكات!K:K, "سيدات") -> 0 | E21: =C21-D21 -> 0
A22: برايفت 30 حصة رجال | B22: =COUNTIFS(الاشتراكات!D:D,"برايفت 30 حصص",الاشتراكات!K:K,"رجال") -> 0 | C22: =SUMIFS(الاشتراكات!E:E, الاشتراكات!D:D, "برايفت 30 حصص", الاشتراكات!K:K, "رجال") -> 0 | D22: =SUMIFS(الاشتراكات!F:F, الاشتراكات!D:D, "برايفت 30 حصص", الاشتراكات!K:K, "رجال") -> 0 | E22: =C22-D22 -> 0
A23: برايفت 30 حصة سيدات | B23: =COUNTIFS(الاشتراكات!D:D,"برايفت 30 حصص",الاشتراكات!K:K,"سيدات") -> 0 | C23: =SUMIFS(الاشتراكات!E:E, الاشتراكات!D:D, "برايفت 30 حصص", الاشتراكات!K:K, "سيدات") -> 0 | D23: =SUMIFS(الاشتراكات!F:F, الاشتراكات!D:D, "برايفت 20 حصص", الاشتراكات!K:K, "سيدات") -> 0 | E23: =C23-D23 -> 0
A24: حصة برايفت رجال | B24: =COUNTIFS(الاشتراكات!D:D,"حصة برايفت",الاشتراكات!K:K,"رجال") -> 0 | C24: =SUMIFS(الاشتراكات!E:E, الاشتراكات!D:D, "حصة برايفت", الاشتراكات!K:K, "رجال") -> 0 | D24: =SUMIFS(الاشتراكات!F:F, الاشتراكات!D:D, "حصة برايفت", الاشتراكات!K:K, "رجال") -> 0 | E24: =C24-D24 -> 0
A25: حصة برايفت سيدات | B25: =COUNTIFS(الاشتراكات!D:D,"حصة برايفت",الاشتراكات!K:K,"سيدات") -> 0 | C25: =SUMIFS(الاشتراكات!E:E, الاشتراكات!D:D, "حصة برايفت", الاشتراكات!K:K, "سيدات") -> 0 | D25: =SUMIFS(الاشتراكات!F:F, الاشتراكات!D:D, "حصة برايفت", الاشتراكات!K:K, "سيدات") -> 0 | E25: =C25-D25 -> 0
A26: جدول تدريب رجال | B26: =COUNTIFS(الاشتراكات!D:D,"جدول تدريب",الاشتراكات!K:K,"رجال") -> 0 | C26: =SUMIFS(الاشتراكات!E:E, الاشتراكات!D:D, "جدول تدريب", الاشتراكات!K:K, "رجال") -> 0 | D26: =SUMIFS(الاشتراكات!F:F, الاشتراكات!D:D, "جدول تدريب", الاشتراكات!K:K, "رجال") -> 0 | E26: =C26-D26 -> 0
A27: جدول تدريب سيدات | B27: =COUNTIFS(الاشتراكات!D:D,"جدول تدريب",الاشتراكات!K:K,"سيدات") -> 0 | C27: =SUMIFS(الاشتراكات!E:E, الاشتراكات!D:D, "جدول تدريب", الاشتراكات!K:K, "سيدات") -> 0 | D27: =SUMIFS(الاشتراكات!F:F, الاشتراكات!D:D, "جدول تدريب", الاشتراكات!K:K, "سيدات") -> 0 | E27: =C27-D27 -> 0
A28: جدول تغذية رجال | B28: =COUNTIFS(الاشتراكات!D:D,"جدول تغذية",الاشتراكات!K:K,"رجال") -> 0 | C28: =SUMIFS(الاشتراكات!E:E, الاشتراكات!D:D, "جدول تغذية", الاشتراكات!K:K, "رجال") -> 0 | D28: =SUMIFS(الاشتراكات!F:F, الاشتراكات!D:D, "جدول تغذية", الاشتراكات!K:K, "رجال") -> 0 | E28: =C28-D28 -> 0
A29: جدول تغذية سيدات | B29: =COUNTIFS(الاشتراكات!D:D,"جدول تغذية",الاشتراكات!K:K,"سيدات") -> 0 | C29: =SUMIFS(الاشتراكات!E:E, الاشتراكات!D:D, "جدول تغذية", الاشتراكات!K:K, "سيدات") -> 0 | D29: =SUMIFS(الاشتراكات!F:F, الاشتراكات!D:D, "جدول تغذية", الاشتراكات!K:K, "سيدات") -> 0 | E29: =C29-D29 -> 0
A30: حصة يومي | B30: =COUNTIFS(الاشتراكات!D:D,"حصة يومي") -> 3 | C30: =SUMIFS(الاشتراكات!E:E, الاشتراكات!D:D, "حصة يومي") -> 300 | D30: =SUMIFS(الاشتراكات!F:F, الاشتراكات!D:D, "حصة يومي") -> 300 | E30: =C30-D30 -> 0
A31: غرامة | B31: =COUNTIFS(الاشتراكات!D:D,"غرامة") -> 0 | C31: =SUMIFS(الاشتراكات!E:E, الاشتراكات!D:D, "غرامة") -> 0 | D31: =SUMIFS(الاشتراكات!F:F, الاشتراكات!D:D, "غرامة") -> 0 | E31: =C31-D31 -> 0
A32: باقى اشتراك | B32: =COUNTIFS(الاشتراكات!D:D,"باقي الاشتراك") -> 7 | C32: =SUMIFS(الاشتراكات!E:E, الاشتراكات!D:D, "باقي الاشتراك") -> 4100 | D32: =SUMIFS(الاشتراكات!F:F, الاشتراكات!D:D, "باقي الاشتراك") -> 4100 | E32: =C32-D32 -> 0
A33: احمد سيف | B33: =COUNTIFS(الاشتراكات!C:C,"احمد سيف") -> 0 | C33: =SUMIFS(الاشتراكات!E:E,الاشتراكات!C:C,"احمد سيف") -> 0 | D33: =SUMIFS(الاشتراكات!F:F,الاشتراكات!C:C,"احمد سيف") -> 0 | E33: =C33-D33 -> 0

Sheet مصاريف
A1: البند | B1: المبلغ | C1: التاريخ
A2: مرتبات | B2: 14850 | D2: =SUM(مرتبات!F:F) -> 14850
A3: سلف | B3: =SUM(مرتبات!C:C) -> 3700
A4: مياه | B4: 2600 | C4: 46054
A5: نت | B5: 100 | C5: 04-02-2026
A6: كهرباء | B6: 300 | C6: 07-02-2026
A7: كهرباء | B7: 500 | C7: 14-02-2026
A8: ايجار | B8: 10000
A9: كهرباء | B9: 300 | C9: 20-02-2026
A10: ايجار | B10: 7400 | C10: 20-02-2026
A11: انترنيت | B11: 290 | C11: 20-02-2026
A12: كهرباء | B12: 500 | C12: 25-02-2026

Sheet مرتبات
B1: مرتب | C1: سلف | D1: خصومات | E1: ملحوظات | F1: اجمالى
A2: كابتن خالد | B2: 3500 | C2: 3000 | E2: سلفة | F2: =B2-C2 -> 500
A3: اشرقت | B3: 2700 | C3: 700 | E3: سلفة | F3: =B3-C3 -> 2000
A4: محمد خالد | B4: 1600 | F4: =B4-C4 -> 1600
A5: عمر علاء | B5: 3250 | F5: =B5-C5 -> 3250 | G5: 750
A6: مصطفى | B6: 5000 | E6: سلفة | F6: =B6-C6 -> 5000
A7: برايفت كابتن خالد | B7: =SUMIF(الاشتراكات!I:I, "كابتن خالد", الاشتراكات!E:E)/2 -> 1500 | F7: =B7-C7 -> 1500
A8: برايفت كابتن اشرقت | B8: =SUMIF(الاشتراكات!I:I, "كابتن اشرقت", الاشتراكات!E:E)/2 -> 1000 | F8: =B8-C8 -> 1000
